Workbook

Sheet 表紙
A1: エクソソーム仕入・販売トレーサビリティ管理システム（EXO-TRACE）
A2: 詳細設計書
A4: 版数 | B4: 1.0
A5: 作成日 | B5: 2026-10-04
A6: 最終更新日 | B6: 2026-10-04
A7: 作成 | B7: Claude（自動生成・自己レビュー済）
A8: 生成元 | B8: docs/design/tools/spec.py → build.py（設計変更は spec.py を編集し再生成）
A10: 設計規模サマリ（各シートから自動集計）
A11: 機能数 | B11: =COUNTA(機能一覧!A4:A2000) -> 34
A12: うち MUST | B12: =COUNTIF(機能一覧!E:E,"MUST") -> 27
A13: 画面数 | B13: =COUNTA(画面一覧!A4:A2000) -> 24
A14: 画面項目数 | B14: =COUNTA(画面項目定義!A4:A2000) -> 155
A15: API数 | B15: =COUNTA(API一覧!A4:A2000) -> 50
A16: テーブル数 | B16: =COUNTA(テーブル一覧!A4:A2000) -> 26
A17: カラム数（共通カラム含む） | B17: =SUM(テーブル一覧!E:E) -> 353
A18: 業務ルール数 | B18: =COUNTA(業務ルール!A4:A2000) -> 20
A19: 未対応の課題 | B19: =COUNTIF(課題一覧!F:F,"未対応") -> 10
A20: レビュー指摘数（累計） | B20: =COUNTA(レビュー記録!A4:A2000) -> 50
A21: うち 対応済 | B21: =COUNTIF(レビュー記録!F:F,"対応済") -> 50
A23: 目次（クリックで移動）
A24: No | B24: シート | C24: 内容
A25: 1 | B25: 改訂履歴 | C25: 版ごとの変更内容
A26: 2 | B26: レビュー記録 | C26: 自己レビュー（修正ループ）の指摘と対応
A27: 3 | B27: システム概要 | C27: 目的・スコープ・前提・構成
A28: 4 | B28: 業務フロー | C28: 業務の流れと関連機能・データ
A29: 5 | B29: 機能一覧 | C29: 機能ID・優先度・関連画面
A30: 6 | B30: 画面一覧 | C30: 画面ID・概要・操作
A31: 7 | B31: 画面項目定義 | C31: 主要画面の入出力項目とチェック
A32: 8 | B32: API一覧 | C32: REST API・許可ロール・処理詳細
A33: 9 | B33: 処理詳細 | C33: 主要処理のステップ・トランザクション・エラー
A34: 10 | B34: 業務ルール | C34: 業務ルール・バリデーション
A35: 11 | B35: 状態遷移 | C35: ロット/発注/受注/出荷/回収の状態遷移
A36: 12 | B36: テーブル一覧 | C36: テーブル一覧（ER概要）
... A47: 23 | B47: 課題一覧 | C47: 未決事項・確認事項
A49: 凡例
B50: 表の見出し
B51: グループ見出し（テーブル名・処理名等）
B52: トレーサビリティ上の重要項目（★）
B53: 課題一覧：ステータス／回答欄は記入可（プルダウン）

Sheet 改訂履歴
A1: 改訂履歴 | E1: ← 表紙へ
A3: 版 | B3: 日付 | C3: 区分 | D3: 内容 | E3: 作成/修正者
A4: 0.1 | B4: 2026-10-04 | C4: 新規 | D4: 初版作成（概要・機能・画面・テーブル・項目定義・権限・非機能） | E4: Claude
A5: 0.2 | B5: 2026-10-04 | C5: 修正 | D5: 詳細設計へ拡張（画面項目定義・API・処理詳細・主要SQL・インデックス・メッセージ・バッチ・DDL）。第1回 自動整合性チェック指摘18件を修正 | E5: Claude
A6: 0.3 | B6: 2026-10-04 | C6: 修正 | D6: 第2回 設計レビュー指摘20件を修正（分納・ロット単位引当解除・回収品受入・排他制御・温度逸脱の遡及判定・返品の隔離保管・ステータス履歴・入荷取消・受注打切り等）。DDL/SQLの実DB検証で判明した初期ユーザー投入手順を追記 | E6: Claude
A7: 0.4 | B7: 2026-10-04 | C7: 修正 | D7: 第3回 再レビュー指摘15件を修正（ロック順序の統一 P-00、未検品保留の解除先、分納時のロット状態別処理と隔離入庫・分納受入判定、回収対象の再抽出の消滅分更新、与信承認フロー、仕入先返品、回収登録/抽出の分離、ロットステータス変更処理、全MUST画面の項目定義） | E7: Claude
A8: 1.0 | B8: 2026-10-04 | C8: 確定 | D8: 第4回 収束確認の指摘6件を修正（隔離在庫の出所別管理、受注ロックと与信再判定、発注打切り状態、回収のロック順序、回収進捗更新の権限と自動判定、仕入先返品の参照伝票）。全自動チェック・実DB検証を通過し初版確定 | E8: Claude

Sheet レビュー記録
A1: レビュー記録（自己修正ループ） | G1: ← 表紙へ
A2: 自動整合性チェック（tools/check.py）と、別エージェントによる設計レビューの指摘・対応を記録
A3: No | B3: 回 | C3: 観点 | D3: 指摘内容 | E3: 対応内容 | F3: 状態 | G3: 対応版
A4: R-01 | B4: 1 | C4: 参照整合（業務ルール） | D4: BR-01/02/03/05/14 がどの処理詳細からも参照されていない（実装時に漏れる） | E4: P-04/P-05/P-06/P-08 の該当ステップにルールIDを明記 | F4: 対応済 | G4: 0.2
A5: R-02 | B5: 1 | C5: 権限×API | D5: API-018（販売可否ルール）が全ロール許可だが、権限マトリクスでは VIEWER 不可 | E5: 許可ロールを ADMIN,QA に限定（ADMIN登録→QA承認） | F5: 対応済 | G5: 0.2
A6: R-03 | B6: 1 | C6: 権限×API | D6: API-033（添付）が ADMIN/WAREHOUSE に更新許可だが、権限マトリクス RCV-02 は参照のみ | E6: 添付アップロードを QA に限定 | F6: 対応済 | G6: 0.2
A7: R-04 | B7: 1 | C7: 権限×API | D7: 権限マトリクス INV-03 で QA=A（承認）だが、承認APIが存在しない | E7: INV-03 の QA を R に変更（調整・廃棄は理由必須＋監査ログで統制） | F7: 対応済 | G7: 0.2
A8: R-05 | B8: 1 | C8: 権限×API | D8: 権限マトリクス SHP-03（納品書）で C が付いているが、対応APIは参照（GET）のみ | E8: SHP-03 を R に変更し API許可ロールと一致 | F8: 対応済 | G8: 0.2
A9: R-06 | B9: 1 | C9: コード値 | D9: 由来・形態・ロールのコード定義がない | E9: コード定義シートに追加 | F9: 対応済 | G9: 0.2
A10: R-07 | B10: 1 | C10: コード値 | D10: 保管温度区分・規制区分・顧客区分のカラム備考が日本語名、コード定義は英字コードで不一致 | E10: 備考を英字コードに統一（DBはコード、画面は名称） | F10: 対応済 | G10: 0.2
A11: R-08 | B11: 1 | C11: メッセージ | D11: 温度逸脱メッセージが『警告』なのにIDがエラー系（MSG-E17） | E11: MSG-W05 に変更。ID接頭辞と種別の一致を自動チェックに追加 | F11: 対応済 | G11: 0.2
A12: R-09 | B12: 2 | C12: 業務（分納） | D12: 同一仕入先ロットが分納されると2回目の入荷が重複エラーになる | E12: P-01 で既存ロットに加算（使用期限一致必須）。入荷明細:ロット＝多:1。BR-15・MSG-E05 改訂 | F12: 対応済 | G12: 0.3
A13: R-10 | B13: 2 | C13: 業務（引当） | D13: HOLD/EXPIRED/RECALLED 時に引当が残り廃棄できない。回収時に他ロット明細まで取消される | E13: ロット指定の引当解除 P-11 を新設し P-08/P-09/B-01/LOT-02 から呼出。出荷明細に status を追加し明細単位で解除 | F13: 対応済 | G13: 0.3
A14: R-11 | B14: 2 | C14: 状態遷移 | D14: QUARANTINE→HOLD、HOLD→EXPIRED、期限切れ後の回収、REJECTED後の扱いが未定義。保留解除で COA なしに合格できる | E14: 状態遷移を網羅し、BR-17（保留解除は COA 添付かつ検品済）を追加 | F14: 対応済 | G14: 0.3
A15: R-12 | B15: 2 | C15: トレーサビリティ（回収） | D15: 回収品の物理受入が在庫・返品に記録されず、追跡結果に反映されない | E15: 返品に recall_target_id を追加し回収品は返品登録で受入。recovered_qty は返品から自動集計。BR-18（回収品は廃棄のみ） | F15: 対応済 | G15: 0.3
... A53: R-50 | B53: 4 | C53: 処理（仕入先返品） | D53: 移行ロット・分納ロットで参照する入荷明細が決まらない | E53: 返品元入荷明細を利用者が選択（残数上限）、移行ロットは ref_type=migration・単価は t_lot.unit_cost | F53: 対応済 | G53: 1.0

Sheet システム概要
A1: システム概要 | B1: ← 表紙へ
A3: 項目 | B3: 内容
A4: 目的 | B4: エクソソーム製品（原料・製剤）の仕入から在庫・販売・回収までをロット単位で一元管理し、「どのロットを・いつ・どの顧客に・どれだけ販売したか」を即時に追跡できる状態にする。
A5: 背景・課題 | B5: 現状は仕入台帳・在庫表・販売台帳がExcel等で分散しており、①ロットと販売先の紐付けが手作業 ②使用期限切れ・温度逸脱の見落とし ③品質問題発生時に販売先の特定に時間がかかる、という課題がある。
A6: スコープ（対象） | B6: 仕入先・商品・顧客マスタ管理／発注／入荷・受入検品／ロット・在庫管理／受注・出荷（ロット引当）／返品／回収（リコール）／温度記録／帳票・CSV出力／監査ログ
A7: スコープ（対象外） | B7: 会計システム本体（仕訳はCSV連携のみ）／ECサイト／患者・施術記録（医療機関側の管理範囲）
A8: 利用者 | B8: 経営者・管理者、仕入担当、倉庫（入出庫）担当、営業担当、品質保証（QA）担当
A9: 想定規模 | B9: 商品 〜100品目／顧客 〜2,000件／ロット 〜1,000件/年／出荷 〜10,000明細/年／同時利用 〜20名
A10: トレーサビリティの原則 | B10: ①全ての在庫はロット番号（＋保管場所）単位で保持する ②出荷明細には必ずロットを紐付ける（ロット未指定の出荷は登録不可） ③在庫数量の増減は全て在庫移動履歴に記録し、直接更新しない ④確定済み伝票は物理削除せず、取消伝票（赤伝）で打ち消す
A11: 規制・コンプライアンス前提 | B11: エクソソーム製品の法的区分（化粧品原料／研究用試薬／医療機関向け自由診療用途等）は商品ごとに『規制区分』として保持し、区分に応じて販売可能な顧客区分を制限する。法規制（薬機法・再生医療等安全性確保法の改正動向等）は導入前に専門家確認を要する（課題一覧 参照）。
A12: システム構成（提案） | B12: Webアプリケーション（ブラウザ利用）。フロント：Next.js(TypeScript)／API：Node.js／DB：PostgreSQL／ファイル保管：オブジェクトストレージ（COA等PDF）／認証：メール＋パスワード＋2要素認証。小規模で先行する場合は Google スプレッドシート＋AppSheet での簡易版も可（非機能要件 参照）。

Sheet 業務フロー
A1: 業務フロー | G1: ← 表紙へ
A2: 仕入 → 受入検品 → 保管 → 受注 → ロット引当・出荷 → 返品／回収 の流れ。全工程でロット番号を引き継ぐ
A3: No | B3: 業務 | C3: ステップ | D3: 担当 | E3: 内容 | F3: 関連機能ID | G3: 生成/更新データ
A4: F-01 | B4: 仕入 | C4: 発注 | D4: 仕入担当 | E4: 仕入先・商品・数量・希望納期を指定して発注書を作成し、承認後に仕入先へ送付する。 | F4: PUR-01,PUR-02 | G4: t_purchase_order, t_purchase_order_line
A5: F-02 | B5: 仕入 | C5: 入荷登録 | D5: 倉庫担当 | E5: 納品物を発注と照合し、仕入先ロット番号・製造日・使用期限・数量・到着時温度を登録する。入荷時点のロットは『検品待ち』で、引当不可。 | F5: RCV-01 | G5: t_receipt, t_receipt_line, t_lot, t_inventory, t_stock_movement
A6: F-03 | B6: 仕入 | C6: 受入検品 | D6: QA担当 | E6: COA（試験成績書）・外観・温度記録を確認し、ロットを『合格』『不合格』『保留』に判定する。合格のみ出荷引当可能になる。 | F6: RCV-02,LOT-02 | G6: t_lot, t_attachment
A7: F-04 | B7: 在庫 | C7: 保管・温度管理 | D7: 倉庫担当 | E7: 保管場所（冷凍庫等）ごとに温度を記録する。許容範囲外は温度逸脱として該当在庫ロットを『保留』にする。 | F7: INV-04 | G7: t_temperature_log, t_lot
A8: F-05 | B8: 販売 | C8: 受注 | D8: 営業担当 | E8: 顧客・納品先・商品・数量を登録する。商品の規制区分と顧客区分の組合せが販売不可の場合は登録できない。 | F8: SAL-01 | G8: t_sales_order, t_sales_order_line
A9: F-06 | B9: 販売 | C9: 出荷（ロット引当） | D9: 倉庫担当 | E9: 受注明細に対してロットを引当（既定は使用期限の近い順＝FEFO）し、出荷を確定する。出荷時点で残存有効期間が商品ごとの最低出荷残期間を下回るロットは引当不可。 | F9: SHP-01,SHP-02 | G9: t_shipment, t_shipment_line, t_inventory, t_stock_movement
A10: F-07 | B10: 販売 | C10: 納品書・請求 | D10: 営業担当 | E10: 出荷確定後に納品書（ロット番号・使用期限記載）を発行し、請求データを会計連携CSVで出力する。 | F10: SHP-03,RPT-05 | G10: —
A11: F-08 | B11: 販売 | C11: 返品 | D11: 倉庫担当 | E11: 返品を元出荷明細（＝ロット）に紐付けて隔離保管場所に受入れ、QA判定後に在庫戻し or 廃棄とする。回収品は廃棄のみ。 | F11: RET-01 | G11: t_return, t_inventory, t_stock_movement, t_recall_target
A12: F-09 | B12: 品質 | C12: 回収（リコール） | D12: QA担当 | E12: 対象ロットを指定すると、出荷先顧客・数量を自動抽出する。ロットを『回収』にして出荷停止し、納品先ごとの連絡・回収状況を管理する。回収品の受入は返品登録で行い回収数量に自動反映。 | F12: RCL-01,RCL-02,TRC-01,RET-01 | G12: t_recall, t_recall_lot, t_recall_target, t_return, t_lot
A13: F-10 | B13: 管理 | C13: 棚卸 | D13: 倉庫担当 | E13: 保管場所×ロット単位で実数をカウントし、差異は理由付きの在庫調整として記録する。 | F13: INV-03 | G13: t_stock_movement, t_inventory

Sheet 機能一覧
A1: 機能一覧 | F1: ← 表紙へ
A2: 優先度：MUST＝初期リリース必須／SHOULD＝初期リリース推奨／COULD＝将来
A3: 機能ID | B3: 大分類 | C3: 機能名 | D3: 概要 | E3: 優先度 | F3: 関連画面ID
A4: MST-01 | B4: マスタ | C4: 仕入先管理 | D4: 仕入先の登録・編集・無効化。取引条件・連絡先・取引開始日を保持。 | E4: MUST | F4: SCR-11
A5: MST-02 | B5: マスタ | C5: 商品管理 | D5: 商品の登録・編集・無効化。形態・由来・保管温度区分・有効期間・最低出荷残期間・規制区分を保持。 | E5: MUST | F5: SCR-12
A6: MST-03 | B6: マスタ | C6: 顧客管理 | D6: 顧客（医療機関・サロン・代理店等）と納品先の登録・編集。顧客区分・医療機関コード・与信限度額を保持。 | E6: MUST | F6: SCR-13
A7: MST-04 | B7: マスタ | C7: 保管場所管理 | D7: 倉庫・冷凍庫等の保管場所と許容温度範囲の登録。 | E7: MUST | F7: SCR-14
A8: MST-05 | B8: マスタ | C8: ユーザー・権限管理 | D8: ユーザーの登録、ロール割当、アカウント停止。 | E8: MUST | F8: SCR-15
A9: MST-06 | B9: マスタ | C9: 販売可否ルール管理 | D9: 商品の規制区分×顧客区分ごとの販売可否を設定。 | E9: MUST | F9: SCR-16
A10: PUR-01 | B10: 仕入 | C10: 発注登録 | D10: 発注書の作成・編集・取消。 | E10: SHOULD | F10: SCR-21
A11: PUR-02 | B11: 仕入 | C11: 発注承認・発注書出力 | D11: 管理者による承認と発注書PDFの出力。 | E11: SHOULD | F11: SCR-21
A12: RCV-01 | B12: 仕入 | C12: 入荷登録 | D12: 発注引当または発注なしでの入荷登録・取消。ロット自動生成／分納時は既存ロットへ加算。 | E12: MUST | F12: SCR-22
A13: RCV-02 | B13: 仕入 | C13: 受入検品 | D13: COA添付、検品結果の登録、ロット判定（合格/不合格/保留）、分納受入判定。 | E13: MUST | F13: SCR-23
A14: LOT-01 | B14: ロット | C14: ロット一覧・詳細 | D14: ロットごとの基本情報・在庫・入出荷履歴・添付書類の参照。 | E14: MUST | F14: SCR-31,SCR-32
... A37: SYS-03 | B37: 共通 | C37: ダッシュボード | D37: アラート、当日の入荷予定・出荷予定、回収案件の状況。 | E37: MUST | F37: SCR-01

Sheet 画面一覧
A1: 画面一覧 | E1: ← 表紙へ
A3: 画面ID | B3: 画面名 | C3: 区分 | D3: 概要 | E3: 主な操作
A4: SCR-00 | B4: ログイン | C4: 共通 | D4: 認証画面 | E4: ログイン、2要素認証、パスワード再設定
A5: SCR-01 | B5: ダッシュボード | C5: 共通 | D5: アラート・当日予定・回収状況の表示 | E5: 各アラートから該当画面へ遷移
A6: SCR-11 | B6: 仕入先一覧・編集 | C6: マスタ | D6: 仕入先の検索・登録・編集 | E6: 検索、新規、編集、無効化
A7: SCR-12 | B7: 商品一覧・編集 | C7: マスタ | D7: 商品の検索・登録・編集 | E7: 検索、新規、編集、無効化
A8: SCR-13 | B8: 顧客一覧・編集 | C8: マスタ | D8: 顧客・納品先の検索・登録・編集 | E8: 検索、新規、編集、納品先追加、無効化
A9: SCR-14 | B9: 保管場所一覧・編集 | C9: マスタ | D9: 保管場所の登録・編集 | E9: 新規、編集、無効化
A10: SCR-15 | B10: ユーザー管理 | C10: マスタ | D10: ユーザー・ロールの管理 | E10: 新規、ロール変更、停止
A11: SCR-16 | B11: 販売可否ルール | C11: マスタ | D11: 規制区分×顧客区分のマトリクス編集 | E11: 編集
A12: SCR-21 | B12: 発注一覧・登録 | C12: 仕入 | D12: 発注の検索・登録・承認 | E12: 新規、編集、承認、取消、発注書PDF
A13: SCR-22 | B13: 入荷登録 | C13: 仕入 | D13: 発注を選択して入荷・ロット情報を登録 | E13: 発注選択、ロット入力、確定
A14: SCR-23 | B14: 受入検品 | C14: 仕入 | D14: 検品待ちロットの判定 | E14: COA添付、判定登録
... A27: SCR-62 | B27: 監査ログ照会 | C27: 共通 | D27: 操作履歴の検索 | E27: 検索、CSV出力

Sheet 画面項目定義
A1: 画面項目定義 | K1: ← 表紙へ
A2: 主要画面（入荷・検品・受注・出荷・追跡・回収）の項目。マスタ画面は項目定義シートのカラムをそのまま入力項目とする
A3: 画面ID | B3: 画面名 | C3: No | D3: 項目名 | E3: 種別 | F3: 入出力 | G3: 必須 | H3: 桁/形式 | I3: 対応テーブル.カラム | J3: 初期値 | K3: チェック・備考
A4: SCR-01 | B4: ダッシュボード | C4: 1 | D4: アラート一覧 | E4: 一覧 | F4: 出力 | I4: （アラート） | K4: BR-16 の種類別件数と明細。クリックで該当画面へ
A5: SCR-01 | B5: ダッシュボード | C5: 2 | D5: 本日の入荷予定 | E5: 一覧 | F5: 出力 | I5: t_purchase_order | K5: 入荷予定日=当日 の APPROVED/PARTIAL
A6: SCR-01 | B6: ダッシュボード | C6: 3 | D6: 本日の出荷予定 | E6: 一覧 | F6: 出力 | I6: t_sales_order | K6: 希望納期<=当日 の OPEN/PARTIAL。CREDIT_PENDING は別枠表示
A7: SCR-01 | B7: ダッシュボード | C7: 4 | D7: 検品待ち・分納受入待ち | E7: 件数 | F7: 出力 | I7: t_lot | K7: QAロール向け
A8: SCR-01 | B8: ダッシュボード | C8: 5 | D8: 回収案件の状況 | E8: 一覧 | F8: 出力 | I8: t_recall, t_recall_target | K8: 未完了案件ごとの連絡済率・回収率
A9: SCR-11 | B9: 仕入先一覧・編集 | C9: 1 | D9: 仕入先コード | E9: テキスト | F9: 入力 | G9: Y | H9: 20 | I9: m_supplier.supplier_code | K9: 一意
A10: SCR-11 | B10: 仕入先一覧・編集 | C10: 2 | D10: 仕入先名・国・住所・担当者・電話・メール・支払条件 | E10: テキスト | F10: 入力 | H10: 項目定義に従う | I10: m_supplier.name | K10: 仕入先名は必須
A11: SCR-11 | B11: 仕入先一覧・編集 | C11: 3 | D11: 有効フラグ | E11: チェック | F11: 入力 | G11: Y | I11: m_supplier.is_active | J11: ON | K11: 無効化しても過去伝票は参照可
A12: SCR-12 | B12: 商品一覧・編集 | C12: 1 | D12: 商品コード | E12: テキスト | F12: 入力 | G12: Y | H12: 20 | I12: m_product.product_code | K12: 一意。英数字・ハイフン（ロット番号に使用）
A13: SCR-12 | B13: 商品一覧・編集 | C13: 2 | D13: 商品名 | E13: テキスト | F13: 入力 | G13: Y | H13: 100 | I13: m_product.name
A14: SCR-12 | B14: 商品一覧・編集 | C14: 3 | D14: 主仕入先 | E14: 選択 | F14: 入力 | I14: m_product.supplier_id
A15: SCR-12 | B15: 商品一覧・編集 | C15: 4 | D15: 由来・形態 | E15: 選択 | F15: 入力 | G15: Y | H15: コード定義 | I15: m_product.source_type | K15: 形態は m_product.form
A16: SCR-12 | B16: 商品一覧・編集 | C16: 5 | D16: 粒子濃度・内容量・販売単位 | E16: 数値/テキスト | F16: 入力 | H16: 項目定義に従う | I16: m_product.particle_conc
A17: SCR-12 | B17: 商品一覧・編集 | C17: 6 | D17: 保管温度区分 | E17: 選択 | F17: 入力 | G17: Y | H17: コード定義 | I17: m_product.storage_class | K17: 入荷・移動先の保管場所を制限（BR-06）
A18: SCR-12 | B18: 商品一覧・編集 | C18: 7 | D18: 有効期間（日） | E18: 数値 | F18: 入力 | G18: Y | H18: 整数 | I18: m_product.shelf_life_days | K18: 使用期限の初期値計算用
A19: SCR-12 | B19: 商品一覧・編集 | C19: 8 | D19: 最低出荷残期間（日） | E19: 数値 | F19: 入力 | G19: Y | H19: 整数 | I19: m_product.min_remaining_days | J19: 90 | K19: BR-04
A20: SCR-12 | B20: 商品一覧・編集 | C20: 9 | D20: 規制区分 | E20: 選択 | F20: 入力 | G20: Y | H20: コード定義 | I20: m_product.regulatory_class | K20: 販売可否ルール（BR-09）の判定キー
A21: SCR-12 | B21: 商品一覧・編集 | C21: 10 | D21: 標準原価・標準売価・発注点 | E21: 数値 | F21: 入力 | H21: 項目定義に従う | I21: m_product.list_price | K21: 発注点は在庫下限アラート（BR-16）
A22: SCR-12 | B22: 商品一覧・編集 | C22: 11 | D22: 有効フラグ | E22: チェック | F22: 入力 | G22: Y | I22: m_product.is_active | J22: ON
A23: SCR-13 | B23: 顧客一覧・編集 | C23: 1 | D23: 顧客コード・顧客名 | E23: テキスト | F23: 入力 | G23: Y | H23: 20/100 | I23: m_customer.customer_code | K23: コードは一意
A24: SCR-13 | B24: 顧客一覧・編集 | C24: 2 | D24: 顧客区分 | E24: 選択 | F24: 入力 | G24: Y | H24: コード定義 | I24: m_customer.customer_type | K24: 販売可否ルールの判定キー
A25: SCR-13 | B25: 顧客一覧・編集 | C25: 3 | D25: 医療機関コード | E25: テキスト | F25: 入力 | G25: 医療機関Y | H25: 20 | I25: m_customer.medical_inst_code | K25: BR-10
A26: SCR-13 | B26: 顧客一覧・編集 | C26: 4 | D26: 代表者・担当者・住所・電話・メール | E26: テキスト | F26: 入力 | H26: 項目定義に従う | I26: m_customer.contact_name | K26: 住所は必須
A27: SCR-13 | B27: 顧客一覧・編集 | C27: 5 | D27: 与信限度額（円） | E27: 数値 | F27: 入力 | H27: 12,0 | I27: m_customer.credit_limit | K27: 未入力は無制限（BR-11）
A28: SCR-13 | B28: 顧客一覧・編集 | C28: 6 | D28: 納品先一覧 | E28: 一覧（編集可） | F28: 入出力 | I28: m_ship_to | K28: 名称・住所・電話・担当者・メール（回収連絡先）・既定・有効
A29: SCR-13 | B29: 顧客一覧・編集 | C29: 7 | D29: 納品先 担当者・メール | E29: テキスト | F29: 入力 | H29: 50/254 | I29: m_ship_to.email | K29: 回収連絡に使用（担当者は m_ship_to.contact_name）
A30: SCR-13 | B30: 顧客一覧・編集 | C30: 8 | D30: 有効フラグ | E30: チェック | F30: 入力 | G30: Y | I30: m_customer.is_active | J30: ON | K30: 無効顧客は受注・出荷不可（P-03/P-05）
A31: SCR-14 | B31: 保管場所一覧・編集 | C31: 1 | D31: 保管場所コード・名称 | E31: テキスト | F31: 入力 | G31: Y | H31: 20/50 | I31: m_location.location_code | K31: コードは一意
A32: SCR-14 | B32: 保管場所一覧・編集 | C32: 2 | D32: 保管温度区分 | E32: 選択 | F32: 入力 | G32: Y | H32: コード定義 | I32: m_location.storage_class
A33: SCR-14 | B33: 保管場所一覧・編集 | C33: 3 | D33: 許容温度下限・上限（℃） | E33: 数値 | F33: 入力 | G33: Y | H33: 5,1 | I33: m_location.temp_min | J33: 区分の許容例 | K33: 下限 < 上限。温度逸脱判定（BR-07）
A34: SCR-14 | B34: 保管場所一覧・編集 | C34: 4 | D34: 隔離保管フラグ | E34: チェック | F34: 入力 | G34: Y | I34: m_location.is_quarantine | J34: OFF | K34: 返品・分納受入待ち用。引当対象外（BR-04/BR-20）
A35: SCR-14 | B35: 保管場所一覧・編集 | C35: 5 | D35: 有効フラグ | E35: チェック | F35: 入力 | G35: Y | I35: m_location.is_active | J35: ON | K35: 在庫がある場所は無効化不可
A36: SCR-15 | B36: ユーザー管理 | C36: 1 | D36: メール（ログインID）・氏名 | E36: テキスト | F36: 入力 | G36: Y | H36: 254/50 | I36: m_user.email | K36: メールは一意
A37: SCR-15 | B37: ユーザー管理 | C37: 2 | D37: ロール | E37: 選択 | F37: 入力 | G37: Y | H37: コード定義 | I37: m_user.role | K37: 権限マトリクス参照
A38: SCR-15 | B38: ユーザー管理 | C38: 3 | D38: 有効フラグ | E38: チェック | F38: 入力 | G38: Y | I38: m_user.is_active | J38: ON | K38: 停止で即時ログイン不可
A39: SCR-15 | B39: ユーザー管理 | C39: 4 | D39: 2要素認証リセット／ロック解除ボタン | E39: ボタン | F39: — | I39: m_user.failed_login_count | K39: ADMINのみ。監査ログ記録
A40: SCR-16 | B40: 販売可否ルール | C40: 1 | D40: 販売可否マトリクス | E40: マトリクス（チェック） | F40: 入出力 | H40: 規制区分×顧客区分 | I40: m_sales_rule.allowed | J40: 全て不可 | K40: ADMIN が編集し QA が承認して有効化。変更は監査ログ記録
...

Sheet API一覧
A1: API一覧 | G1: ← 表紙へ
A2: 全APIはサーバー側で認証・権限（権限マトリクス）を検証する。更新系は楽観ロック（version）必須。エラーは {code, message_id, message} を返す
A3: API ID | B3: メソッド | C3: パス | D3: 概要 | E3: 関連機能ID | F3: 許可ロール | G3: 処理詳細
A4: API-001 | B4: POST | C4: /api/auth/login | D4: ログイン（2要素認証は /api/auth/mfa） | E4: SYS-01 | F4: 全員
A5: API-010 | B5: GET | C5: /api/suppliers | D5: 仕入先検索 | E5: MST-01 | F5: 全ロール
A6: API-011 | B6: POST/PUT | C6: /api/suppliers[/{id}] | D6: 仕入先登録・更新 | E6: MST-01 | F6: ADMIN
A7: API-012 | B7: GET | C7: /api/products | D7: 商品検索 | E7: MST-02 | F7: 全ロール
A8: API-013 | B8: POST/PUT | C8: /api/products[/{id}] | D8: 商品登録・更新 | E8: MST-02 | F8: ADMIN,PURCHASE
A9: API-014 | B9: GET | C9: /api/customers | D9: 顧客検索 | E9: MST-03 | F9: 全ロール
A10: API-015 | B10: POST/PUT | C10: /api/customers[/{id}] | D10: 顧客・納品先登録・更新 | E10: MST-03 | F10: ADMIN,SALES
A11: API-016 | B11: GET/POST/PUT | C11: /api/locations[/{id}] | D11: 保管場所 | E11: MST-04 | F11: 参照:全ロール／更新:ADMIN,WAREHOUSE
A12: API-017 | B12: GET/POST/PUT | C12: /api/users[/{id}] | D12: ユーザー管理 | E12: MST-05 | F12: ADMIN
A13: API-018 | B13: GET/PUT | C13: /api/sales-rules | D13: 販売可否ルール（更新はADMIN登録→QA承認の2段階） | E13: MST-06 | F13: ADMIN,QA
A14: API-020 | B14: GET/POST/PUT | C14: /api/purchase-orders[/{id}] | D14: 発注検索・登録・更新 | E14: PUR-01 | F14: ADMIN,PURCHASE
A15: API-021 | B15: POST | C15: /api/purchase-orders/{id}/approve | D15: 発注承認 | E15: PUR-02 | F15: ADMIN
... A19: API-030 | B19: POST | C19: /api/receipts | D19: 入荷登録（下書き） | E19: RCV-01 | F19: ADMIN,WAREHOUSE
A20: API-031 | B20: POST | C20: /api/receipts/{id}/confirm | D20: 入荷確定（ロット生成・在庫加算） | E20: RCV-01 | F20: ADMIN,WAREHOUSE | G20: P-01
A21: API-034 | B21: POST | C21: /api/receipts/{id}/cancel | D21: 入荷取消（赤伝） | E21: RCV-01 | F21: ADMIN | G21: P-12
A22: API-035 | B22: POST | C22: /api/receipt-lines/{id}/split-inspection | D22: 分納受入判定 | E22: RCV-02 | F22: QA | G22: P-16
A23: API-032 | B23: POST | C23: /api/lots/{id}/inspection | D23: 受入検品判定 | E23: RCV-02 | F23: QA | G23: P-02
A24: API-033 | B24: POST | C24: /api/attachments | D24: 添付アップロード（COA等） | E24: RCV-02 | F24: QA
A25: API-040 | B25: GET | C25: /api/lots | D25: ロット検索 | E25: LOT-01 | F25: 全ロール
A26: API-041 | B26: GET | C26: /api/lots/{id} | D26: ロット詳細（在庫・履歴・添付） | E26: LOT-01 | F26: 全ロール
A27: API-042 | B27: POST | C27: /api/lots/{id}/status | D27: ロットステータス変更 | E27: LOT-02 | F27: QA | G27: P-15
A28: API-050 | B28: GET | C28: /api/inventory | D28: 在庫照会 | E28: INV-01 | F28: 全ロール
A29: API-051 | B29: POST | C29: /api/stock/transfers | D29: 保管場所間移動 | E29: INV-02 | F29: ADMIN,WAREHOUSE | G29: P-10
A30: API-052 | B30: POST | C30: /api/stock/adjustments | D30: 棚卸調整・廃棄 | E30: INV-03 | F30: ADMIN,WAREHOUSE | G30: P-10
A31: API-055 | B31: POST | C31: /api/stock/supplier-returns | D31: 仕入先返品 | E31: INV-03 | F31: ADMIN,WAREHOUSE | G31: P-17
A32: API-053 | B32: POST | C32: /api/temperature-logs[/import] | D32: 温度記録登録・CSV取込 | E32: INV-04 | F32: ADMIN,WAREHOUSE,QA | G32: P-09
A33: API-054 | B33: GET | C33: /api/alerts | D33: アラート一覧 | E33: INV-05 | F33: 全ロール
A34: API-060 | B34: GET/POST/PUT | C34: /api/sales-orders[/{id}] | D34: 受注検索・登録・更新 | E34: SAL-01 | F34: ADMIN,SALES | G34: P-03
A35: API-062 | B35: POST | C35: /api/sales-orders/{id}/close | D35: 受注残数打切り | E35: SAL-01 | F35: ADMIN,SALES | G35: P-03
A36: API-063 | B36: POST | C36: /api/sales-orders/{id}/credit-approve | D36: 与信超過の承認（CREDIT_PENDING→OPEN） | E36: SAL-01 | F36: ADMIN | G36: P-03
A37: API-061 | B37: POST | C37: /api/sales-orders/{id}/cancel | D37: 受注取消 | E37: SAL-01 | F37: ADMIN,SALES | G37: P-03
A38: API-070 | B38: POST | C38: /api/shipments/allocate | D38: 自動引当（FEFO） | E38: SHP-01 | F38: ADMIN,WAREHOUSE | G38: P-04
A39: API-071 | B39: POST | C39: /api/shipments/{id}/confirm | D39: 出荷確定 | E39: SHP-02 | F39: ADMIN,WAREHOUSE | G39: P-05
A40: API-072 | B40: POST | C40: /api/shipments/{id}/cancel | D40: 引当解除・出荷取消 | E40: SHP-02 | F40: ADMIN,WAREHOUSE（確定後はADMINのみ） | G40: P-06
A41: API-074 | B41: PUT | C41: /api/shipments/{id}/lines | D41: 引当の手動変更（ロット差替え） | E41: SHP-01 | F41: ADMIN,WAREHOUSE | G41: P-13
A42: API-073 | B42: GET | C42: /api/shipments/{id}/delivery-note | D42: 納品書PDF | E42: SHP-03 | F42: ADMIN,WAREHOUSE,SALES
A43: API-080 | B43: POST | C43: /api/returns | D43: 返品登録 | E43: RET-01 | F43: ADMIN,WAREHOUSE | G43: P-07
...

Sheet 処理詳細
A1: 処理詳細 | E1: ← 表紙へ
A2: 特記なき限り各処理は1トランザクション。在庫・ロットの更新は SELECT ... FOR UPDATE で行ロックし、エラー時は全体ロールバック
A3: 処理ID | B3: 処理名 | C3: ステップ | D3: 内容 | E3: エラー時メッセージ
A4: P-00 | B4: 共通：排他制御（ロック順序） | C4: 1 | D4: 対象のロットID・保管場所ID・伝票IDをロックなしで読み取る
A5: P-00 | B5: 共通：排他制御（ロック順序） | C5: 2 | D5: t_lot を id 昇順で FOR UPDATE（状態を変える処理）または FOR SHARE（状態を参照する処理）
A6: P-00 | B6: 共通：排他制御（ロック順序） | C6: 3 | D6: t_inventory を (lot_id, location_id) 昇順で FOR UPDATE
A7: P-00 | B7: 共通：排他制御（ロック順序） | C7: 4 | D7: 伝票（ヘッダ→明細）を FOR UPDATE し、ステータス・version をロック後に再検証（変化していれば MSG-E01） | E7: MSG-E01
A8: P-00 | B8: 共通：排他制御（ロック順序） | C8: 5 | D8: 回収を扱う処理は、伝票の後に t_recall FOR UPDATE → t_recall_target を id 昇順で FOR UPDATE（回収案件ヘッダで直列化）
A9: P-00 | B9: 共通：排他制御（ロック順序） | C9: 6 | D9: 全処理はこの順序（ロット→在庫→伝票→回収）でロックを取得する。以下の各処理の『ロック』はこの手順を指す
A10: P-00 | B10: 共通：排他制御（ロック順序） | C10: 7 | D10: 隔離保管場所からの払出しは必ず出所伝票（ref_type=receipt_line／return）を ref に記録し、払出し可能数＝出所数量−同一 ref での払出し済数量 を上限とする（BR-20） | E10: MSG-E30
A11: P-01 | B11: 入荷確定 | C11: 1 | D11: ロック（P-00）：既存ロット（仕入先,商品,仕入先ロット番号）→ 在庫 → t_receipt。status=DRAFT を確認 | E11: MSG-E01
A12: P-01 | B12: 入荷確定 | C12: 2 | D12: 製造日 <= 入荷日 <= 当日、使用期限 > 入荷日 を検証 | E12: MSG-E06,MSG-E22
A13: P-01 | B13: 入荷確定 | C13: 3 | D13: 既存ロットの状態で分岐（BR-15）：なし→社内ロット番号を採番し INSERT（QUARANTINE、received_on=入荷日）／QUARANTINE→加算／VOID→QUARANTINE に戻す／RELEASED・HOLD→分納（隔離保管場所へ入庫）／REJECTED・RECALLED・EXPIRED→エラー。既存ありの場合は使用期限一致を検証 | E13: MSG-E05,MSG-E25
A14: P-01 | B14: 入荷確定 | C14: 4 | D14: 入庫先を検証（BR-06）：温度区分一致。通常は is_quarantine=false、分納（RELEASED/HOLD）は is_quarantine=true | E14: MSG-E07
A15: P-01 | B15: 入荷確定 | C15: 5 | D15: t_receipt_line.lot_id を設定。t_lot.unit_cost を移動平均で更新：(全保管場所の現在庫×現原価＋入荷数量×仕入単価)÷(現在庫＋入荷数量)
A16: P-01 | B16: 入荷確定 | C16: 6 | D16: t_stock_movement に RECEIPT(+数量) を INSERT、t_inventory を加算（BR-02）。状態変更時は t_lot_status_history を INSERT
A17: P-01 | B17: 入荷確定 | C17: 7 | D17: 発注引当時は t_purchase_order_line.received_qty を加算し、発注ステータスを PARTIAL/RECEIVED に更新
A18: P-01 | B18: 入荷確定 | C18: 8 | D18: t_receipt.status=CONFIRMED、監査ログ記録、コミット。到着時温度が範囲外なら QA へ通知（分納分は P-16 で判定） | E18: MSG-W01
A19: P-02 | B19: 受入検品判定 | C19: 1 | D19: ロック（P-00）：t_lot FOR UPDATE。status=QUARANTINE を確認 | E19: MSG-E01
A20: P-02 | B20: 受入検品判定 | C20: 2 | D20: 判定=合格の場合、doc_type=COA の添付が1件以上あることを検証（BR-08） | E20: MSG-E08
A21: P-02 | B21: 受入検品判定 | C21: 3 | D21: 判定=不合格/保留の場合、理由必須 | E21: MSG-E09
A22: P-02 | B22: 受入検品判定 | C22: 4 | D22: 温度逸脱履歴（温度記録ID付きのステータス履歴）がある場合は警告表示し、合格時は確認チェックを必須とする | E22: MSG-W06
A23: P-02 | B23: 受入検品判定 | C23: 5 | D23: status・status_reason・inspected_by/at を更新し、t_lot_status_history を INSERT。監査ログ（action=STATUS）記録
A24: P-03 | B24: 受注登録・変更 | C24: 1 | D24: 変更・取消・打切り時はロック（P-00）：t_sales_order FOR UPDATE（伝票）し version を検証。顧客が有効、納品先.顧客ID＝顧客ID かつ納品先が有効であることを検証 | E24: MSG-E11,MSG-E01
A25: P-03 | B25: 受注登録・変更 | C25: 2 | D25: 各明細について m_sales_rule(商品.規制区分, 顧客.顧客区分).allowed=true を検証（BR-09） | E25: MSG-E10
A26: P-03 | B26: 受注登録・変更 | C26: 3 | D26: 与信チェック（BR-11）。超過時は警告し、status=CREDIT_PENDING で登録（引当不可）。ADMIN が API-063 で承認すると OPEN | E26: MSG-W03
A27: P-03 | B27: 受注登録・変更 | C27: 4 | D27: 新規：受注番号を採番し INSERT（status=OPEN または CREDIT_PENDING）。在庫の引当はこの時点では行わない
A28: P-03 | B28: 受注登録・変更 | C28: 5 | D28: 変更・取消：ALLOCATED の出荷明細がある明細の商品・数量変更および取消は不可（先に引当解除）。数量は出荷済数量未満にできない。変更で与信を再判定し、超過時は ALLOCATED の出荷がなければ CREDIT_PENDING へ、あればエラー | E28: MSG-E19,MSG-E31
A29: P-04 | B29: 自動引当（FEFO） | C29: 1 | D29: 受注 status=OPEN/PARTIAL を確認。明細ごとに 残数量＝受注数量−出荷済数量−引当中数量 を算出。引当中数量＝当該受注明細の t_shipment_line(status=ALLOCATED).quantity の合計 | E29: MSG-E01
A30: P-04 | B30: 自動引当（FEFO） | C30: 2 | D30: 候補在庫を抽出（BR-04）：lot.status=RELEASED AND lot.product_id=明細.商品 AND lot.expires_on − 出荷日 >= 商品.min_remaining_days AND location.is_quarantine=false AND (on_hand_qty − allocated_qty) > 0
A31: P-04 | B31: 自動引当（FEFO） | C31: 3 | D31: 候補を expires_on ASC, lot.received_on ASC, location_id ASC で並べ（BR-05）、残数量を満たすまで順に割当（複数ロット分割可）
A32: P-04 | B32: 自動引当（FEFO） | C32: 4 | D32: ロック（P-00）：候補ロット FOR SHARE → 在庫 FOR UPDATE → 受注。ロック後に status=RELEASED と引当可能数を再検証し、allocated_qty を加算、t_shipment(ALLOCATED)/t_shipment_line(ALLOCATED) を INSERT | E32: MSG-E12
A33: P-04 | B33: 自動引当（FEFO） | C33: 5 | D33: 残数量を満たせない場合は引当できた分のみ作成し、不足数量を画面に表示 | E33: MSG-W04
A34: P-05 | B34: 出荷確定 | C34: 1 | D34: ロック（P-00）：対象ロット FOR SHARE → 在庫 FOR UPDATE → 受注 → t_shipment・明細 FOR UPDATE。出荷 status=ALLOCATED、受注 status=OPEN/PARTIAL を確認 | E34: MSG-E01
A35: P-05 | B35: 出荷確定 | C35: 2 | D35: ALLOCATED の各明細を再検証：ロットID必須・商品一致（BR-01）、status=RELEASED、残期間条件（BR-04）、顧客・納品先が有効、販売可否ルール（BR-09） | E35: MSG-E13,MSG-E10,MSG-E11
A36: P-05 | B36: 出荷確定 | C36: 3 | D36: t_inventory：on_hand_qty −= 数量、allocated_qty −= 数量（負数になる場合はエラー） | E36: MSG-E12
A37: P-05 | B37: 出荷確定 | C37: 4 | D37: t_stock_movement に SHIPMENT(−数量, ref=shipment_line) を INSERT（BR-02：在庫更新は必ず移動履歴と同一トランザクション）
A38: P-05 | B38: 出荷確定 | C38: 5 | D38: unit_cost に t_lot.unit_cost を設定。明細 status=SHIPPED
A39: P-05 | B39: 出荷確定 | C39: 6 | D39: t_sales_order_line.shipped_qty を加算し受注ステータスを PARTIAL/SHIPPED に更新 | E39: MSG-E23
A40: P-05 | B40: 出荷確定 | C40: 7 | D40: t_shipment.status=SHIPPED、監査ログ記録、コミット
...

Sheet 業務ルール
A1: 業務ルール・バリデーション | D1: ← 表紙へ
A3: ルールID | B3: 区分 | C3: ルール | D3: 関連機能ID
A4: BR-01 | B4: トレーサビリティ | C4: 出荷明細はロットIDを必須とし、ロットの商品と受注明細の商品が一致すること。 | D4: SHP-01
A5: BR-02 | B5: トレーサビリティ | C5: 在庫数量の増減は必ず在庫移動履歴を伴うトランザクションで行う（在庫テーブルの直接更新禁止）。 | D5: SHP-02,INV-03
A6: BR-03 | B6: トレーサビリティ | C6: 確定済の入荷・出荷・返品は物理削除不可。取消は取消区分の移動履歴（赤伝）で行う。 | D6: SHP-02,RCV-01
A7: BR-04 | B7: 品質 | C7: 引当可能な在庫は、ロット.ステータス=RELEASED かつ 使用期限−出荷日 >= 商品.最低出荷残期間 かつ 隔離保管場所でないものに限る。 | D7: SHP-01
A8: BR-05 | B8: 品質 | C8: 自動引当は使用期限の早い順（FEFO）、同一期限は入荷日の早い順とする。 | D8: SHP-01
A9: BR-06 | B9: 品質 | C9: 入庫・移動先の保管場所の保管温度区分は、商品の保管温度区分と一致すること。 | D9: RCV-01,INV-02
A10: BR-07 | B10: 品質 | C10: 温度記録が許容範囲外の場合、測定日時時点で当該保管場所に在庫があったロットを特定し、QUARANTINE/RELEASEDはHOLD、既出荷分は回収候補としてQAへ通知する。 | D10: INV-04
A11: BR-08 | B11: 品質 | C11: 受入検品の合格判定にはCOA（試験成績書）の添付を必須とする。 | D11: RCV-02
A12: BR-09 | B12: 販売 | C12: 受注登録時、商品の規制区分×顧客区分が販売可否ルールで「可」でなければ登録不可。 | D12: SAL-01,MST-06
A13: BR-10 | B13: 販売 | C13: 顧客区分=医療機関の場合、医療機関コードを必須とする。 | D13: MST-03
A14: BR-11 | B14: 販売 | C14: 与信限度額が設定された顧客は、与信残高（未出荷受注残金額＋直近60日の出荷金額）＋今回受注額が限度額を超える場合に警告し、管理者承認で登録可（入金消込は会計側のため簡易算出。課題Q-09）。 | D14: SAL-01
... A23: BR-16 | B23: アラート | C23: 使用期限まで90日/30日、在庫が発注点以下、温度逸脱、回収未対応7日超でダッシュボード表示＋メール通知。 | D23: INV-05

Sheet 状態遷移
A1: 状態遷移 | F1: ← 表紙へ
A3: 対象 | B3: 現状態 | C3: イベント | D3: 次状態 | E3: 条件・処理 | F3: 実行ロール
A4: ロット | B4: （なし） | C4: 入荷確定 | D4: QUARANTINE（検品待ち） | E4: P-01。ロット生成・在庫加算。引当不可 | F4: WAREHOUSE
A5: ロット | B5: QUARANTINE（検品待ち） | C5: 分納入荷 | D5: QUARANTINE（検品待ち） | E5: P-01。数量のみ加算（通常保管場所） | F5: WAREHOUSE
A6: ロット | B6: RELEASED（合格）/HOLD（保留） | C6: 分納入荷 | D6: （状態維持） | E6: P-01。分納分は隔離保管場所へ入庫し、P-16 の分納受入判定まで引当不可 | F6: WAREHOUSE
A7: ロット | B7: VOID（無効） | C7: 再入荷 | D7: QUARANTINE（検品待ち） | E7: P-01。同一仕入先ロットの再入荷。ステータス履歴に記録 | F7: WAREHOUSE
A8: ロット | B8: QUARANTINE（検品待ち） | C8: 検品合格 | D8: RELEASED（合格） | E8: P-02。COA添付必須（BR-08）。inspected_by/at を記録 | F8: QA
A9: ロット | B9: QUARANTINE（検品待ち） | C9: 検品不合格 | D9: REJECTED（不合格） | E9: P-02。理由必須 | F9: QA
A10: ロット | B10: QUARANTINE（検品待ち） | C10: 検品保留 | D10: HOLD（保留） | E10: P-02。理由必須。追加資料待ち等 | F10: QA
A11: ロット | B11: QUARANTINE（検品待ち）/RELEASED（合格） | C11: 温度逸脱 | D11: HOLD（保留） | E11: P-09 で自動。理由＝温度記録ID。引当解除（P-11） | F11: システム
A12: ロット | B12: RELEASED（合格） | C12: 保留 | D12: HOLD（保留） | E12: P-15。理由必須。引当解除（P-11） | F12: QA
A13: ロット | B13: HOLD（保留） | C13: 保留解除（検品済） | D13: RELEASED（合格） | E13: P-15。理由必須。BR-17（COA添付かつ inspected_at あり） | F13: QA
A14: ロット | B14: HOLD（保留） | C14: 保留解除（未検品） | D14: QUARANTINE（検品待ち） | E14: P-15。inspected_at が NULL の場合。以後 P-02 で検品 | F14: QA
... A19: ロット | B19: REJECTED（不合格）/EXPIRED（期限切れ）/RECALLED（回収） | C19: 在庫処分 | D19: （状態維持） | E19: 終端状態。残在庫は仕入先返品（P-17）または廃棄（P-10）で0にする。ロット記録は削除しない | F19: WAREHOUSE
A20: 発注 | B20: DRAFT（作成中） | C20: 承認 | D20: APPROVED（承認済） | F20: ADMIN
A21: 発注 | B21: APPROVED（承認済） | C21: 一部入荷 | D21: PARTIAL（一部入荷） | E21: 入荷済数量 < 発注数量 | F21: WAREHOUSE
A22: 発注 | B22: APPROVED（承認済）/PARTIAL（一部入荷） | C22: 全量入荷 | D22: RECEIVED（入荷完了） | E22: 全明細で入荷済数量 >= 発注数量 | F22: WAREHOUSE
A23: 発注 | B23: PARTIAL（一部入荷）/RECEIVED（入荷完了） | C23: 入荷取消 | D23: APPROVED（承認済）/PARTIAL（一部入荷） | E23: P-12 で入荷済数量を減算し再判定 | F23: ADMIN
A24: 発注 | B24: PARTIAL（一部入荷） | C24: 残数打切り | D24: CLOSED（打切り） | E24: API-024。以後の入荷対象外。理由を備考に記録 | F24: PURCHASE
A25: 発注 | B25: CLOSED（打切り） | C25: 入荷取消 | D25: CLOSED（打切り） | E25: P-12。入荷済数量のみ減算し状態は維持 | F25: ADMIN
A26: 発注 | B26: DRAFT（作成中）/APPROVED（承認済） | C26: 取消 | D26: CANCELLED（取消） | E26: 入荷実績がない場合のみ（MSG-E21） | F26: PURCHASE
A27: 受注 | B27: （なし） | C27: 登録（与信超過） | D27: CREDIT_PENDING（与信承認待ち） | E27: P-03。引当不可 | F27: SALES
A28: 受注 | B28: OPEN（受付）/PARTIAL（一部出荷） | C28: 変更で与信超過 | D28: CREDIT_PENDING（与信承認待ち） | E28: P-03。ALLOCATED の出荷がない場合のみ（あれば MSG-E31） | F28: SALES
A29: 受注 | B29: CREDIT_PENDING（与信承認待ち） | C29: 与信承認 | D29: OPEN（受付）/PARTIAL（一部出荷） | E29: API-063。credit_approved_by/at を記録。出荷済数量で再判定 | F29: ADMIN
A30: 受注 | B30: CREDIT_PENDING（与信承認待ち） | C30: 取消 | D30: CANCELLED（取消） | F30: SALES
A31: 受注 | B31: OPEN（受付） | C31: 一部出荷 | D31: PARTIAL（一部出荷） | F31: WAREHOUSE
A32: 受注 | B32: OPEN（受付）/PARTIAL（一部出荷） | C32: 全量出荷 | D32: SHIPPED（出荷完了） | F32: WAREHOUSE
A33: 受注 | B33: PARTIAL（一部出荷）/SHIPPED（出荷完了） | C33: 出荷取消 | D33: OPEN（受付）/PARTIAL（一部出荷） | E33: P-06 で出荷済数量を減算し再判定 | F33: ADMIN
A34: 受注 | B34: CLOSED（打切り） | C34: 出荷取消 | D34: CLOSED（打切り） | E34: P-06。出荷済数量のみ減算し状態は維持（再出荷しない） | F34: ADMIN
A35: 受注 | B35: PARTIAL（一部出荷） | C35: 残数打切り | D35: CLOSED（打切り） | E35: API-062。ALLOCATED の出荷がないこと（MSG-E19） | F35: SALES
A36: 受注 | B36: OPEN（受付） | C36: 取消 | D36: CANCELLED（取消） | E36: 出荷実績・ALLOCATED の出荷がない場合のみ（MSG-E19） | F36: SALES
A37: 出荷 | B37: ALLOCATED（引当済） | C37: 出荷確定 | D37: SHIPPED（出荷済） | E37: P-05。ALLOCATED の明細のみ SHIPPED にする | F37: WAREHOUSE
A38: 出荷 | B38: ALLOCATED（引当済） | C38: 引当解除（全明細） | D38: CANCELLED（取消） | E38: P-06 / P-11 で ALLOCATED 明細が残らなくなった場合 | F38: WAREHOUSE
A39: 出荷 | B39: SHIPPED（出荷済） | C39: 出荷取消 | D39: CANCELLED（取消） | E39: P-06。赤伝（CANCEL移動）で在庫戻し。返品がある場合は不可 | F39: ADMIN
A40: 回収案件 | B40: （なし） | C40: 登録 | D40: OPEN（登録） | E40: P-08 | F40: QA
A41: 回収案件 | B41: OPEN（登録）/IN_PROGRESS（対応中） | C41: 対象顧客抽出（再抽出） | D41: IN_PROGRESS（対応中） | E41: P-18。何度実行しても同じ結果 | F41: QA
A42: 回収対象 | B42: （なし） | C42: 抽出 | D42: NOT_CONTACTED（未連絡） | E42: P-18。出荷正味0の場合は CLOSED | F42: QA
A43: 回収対象 | B43: NOT_CONTACTED（未連絡） | C43: 連絡 | D43: CONTACTED（連絡済） | E43: API-102 | F43: SALES
A44: 回収対象 | B44: NOT_CONTACTED（未連絡）/CONTACTED（連絡済） | C44: 回収完了 | D44: RECOVERED（回収済） | E44: P-07/P-18/P-19 で自動。回収数量＋回収不能数量 >= 出荷正味数量 | F44: システム
... A46: 回収案件 | B46: IN_PROGRESS（対応中） | C46: 完了 | D46: CLOSED（完了） | E46: P-14。全対象が RECOVERED/CLOSED | F46: QA

Sheet テーブル一覧
A1: テーブル一覧 | F1: ← 表紙へ
A2: カラム数は項目定義シートから COUNTIF で自動集計（グループ見出し行を除く）
A3: 物理名 | B3: 論理名 | C3: 区分 | D3: 概要 | E3: カラム数 | F3: 主な参照先（FK）
A4: m_supplier | B4: 仕入先 | C4: マスタ | D4: 仕入先（製造元・輸入元） | E4: =COUNTIF(項目定義!A:A,A4)-1 -> 15 | F4: —
A5: m_product | B5: 商品 | C5: マスタ | D5: エクソソーム製品・原料 | E5: =COUNTIF(項目定義!A:A,A5)-1 -> 22 | F5: m_supplier
A6: m_customer | B6: 顧客 | C6: マスタ | D6: 販売先（請求先） | E6: =COUNTIF(項目定義!A:A,A6)-1 -> 18 | F6: —
A7: m_ship_to | B7: 納品先 | C7: マスタ | D7: 顧客ごとの納品先 | E7: =COUNTIF(項目定義!A:A,A7)-1 -> 15 | F7: m_customer
A8: m_location | B8: 保管場所 | C8: マスタ | D8: 倉庫・冷凍庫・冷蔵庫等 | E8: =COUNTIF(項目定義!A:A,A8)-1 -> 13 | F8: —
A9: m_sales_rule | B9: 販売可否ルール | C9: マスタ | D9: 規制区分×顧客区分の販売可否 | E9: =COUNTIF(項目定義!A:A,A9)-1 -> 9 | F9: —
A10: m_user | B10: ユーザー | C10: マスタ | D10: システム利用者 | E10: =COUNTIF(項目定義!A:A,A10)-1 -> 13 | F10: —
A11: t_purchase_order | B11: 発注 | C11: トランザクション | D11: 発注ヘッダ | E11: =COUNTIF(項目定義!A:A,A11)-1 -> 14 | F11: m_supplier, m_user
A12: t_purchase_order_line | B12: 発注明細 | C12: トランザクション | D12: 発注明細 | E12: =COUNTIF(項目定義!A:A,A12)-1 -> 12 | F12: m_product, t_purchase_order
A13: t_receipt | B13: 入荷 | C13: トランザクション | D13: 入荷ヘッダ | E13: =COUNTIF(項目定義!A:A,A13)-1 -> 12 | F13: m_supplier, t_purchase_order
A14: t_receipt_line | B14: 入荷明細 | C14: トランザクション | D14: 入荷明細（入荷明細:ロット＝多:1。分納は同一ロットに加算） | E14: =COUNTIF(項目定義!A:A,A14)-1 -> 18 | F14: m_location, m_product, t_lot, t_purchase_order_line, t_receipt
A15: t_lot | B15: ロット | C15: トランザクション | D15: ロット（トレーサビリティの中核） | E15: =COUNTIF(項目定義!A:A,A15)-1 -> 19 | F15: m_product, m_supplier, m_user
... A29: t_audit_log | B29: 監査ログ | C29: ログ | D29: 操作履歴（追記のみ） | E29: =COUNTIF(項目定義!A:A,A29)-1 -> 11 | F29: m_user

Sheet 項目定義
A1: 項目定義 | K1: ← 表紙へ
A2: 各テーブル末尾に共通カラム（created_at/by, updated_at/by, version）を付与。追記のみのテーブル（t_audit_log, t_lot_status_history, t_stock_movement, t_temperature_log）は created_* のみ
A3: テーブル | B3: No | C3: 物理名 | D3: 論理名 | E3: 型 | F3: 桁 | G3: PK | H3: FK参照 | I3: NOT NULL | J3: 初期値 | K3: 備考
A4: m_supplier | B4: 【仕入先】仕入先（製造元・輸入元）
A5: m_supplier | B5: 1 | C5: id | D5: 仕入先ID | E5: BIGINT | G5: Y | I5: Y | J5: 自動採番
A6: m_supplier | B6: 2 | C6: supplier_code | D6: 仕入先コード | E6: VARCHAR | F6: 20 | I6: Y | K6: 一意
A7: m_supplier | B7: 3 | C7: name | D7: 仕入先名 | E7: VARCHAR | F7: 100 | I7: Y
A8: m_supplier | B8: 4 | C8: country | D8: 国 | E8: VARCHAR | F8: 2 | I8: Y | J8: JP | K8: ISO 3166-1
A9: m_supplier | B9: 5 | C9: address | D9: 住所 | E9: VARCHAR | F9: 200
A10: m_supplier | B10: 6 | C10: contact_name | D10: 担当者名 | E10: VARCHAR | F10: 50
A11: m_supplier | B11: 7 | C11: phone | D11: 電話番号 | E11: VARCHAR | F11: 20
A12: m_supplier | B12: 8 | C12: email | D12: メール | E12: VARCHAR | F12: 254
A13: m_supplier | B13: 9 | C13: payment_terms | D13: 支払条件 | E13: VARCHAR | F13: 100 | K13: 例：月末締め翌月末払い
A14: m_supplier | B14: 10 | C14: is_active | D14: 有効フラグ | E14: BOOLEAN | I14: Y | J14: true
A15: m_supplier | B15: 11 | C15: created_at | D15: 作成日時 | E15: TIMESTAMPTZ | I15: Y | J15: 現在日時
A16: m_supplier | B16: 12 | C16: created_by | D16: 作成者 | E16: BIGINT | H16: m_user.id | I16: Y
A17: m_supplier | B17: 13 | C17: updated_at | D17: 更新日時 | E17: TIMESTAMPTZ | I17: Y | J17: 現在日時
A18: m_supplier | B18: 14 | C18: updated_by | D18: 更新者 | E18: BIGINT | H18: m_user.id | I18: Y
A19: m_supplier | B19: 15 | C19: version | D19: 版数 | E19: INTEGER | I19: Y | J19: 1 | K19: 楽観ロック用
A20: m_product | B20: 【商品】エクソソーム製品・原料
A21: m_product | B21: 1 | C21: id | D21: 商品ID | E21: BIGINT | G21: Y | I21: Y | J21: 自動採番
A22: m_product | B22: 2 | C22: product_code | D22: 商品コード | E22: VARCHAR | F22: 20 | I22: Y | K22: 一意
A23: m_product | B23: 3 | C23: name | D23: 商品名 | E23: VARCHAR | F23: 100 | I23: Y
A24: m_product | B24: 4 | C24: supplier_id | D24: 主仕入先ID | E24: BIGINT | H24: m_supplier.id
A25: m_product | B25: 5 | C25: source_type | D25: 由来 | E25: VARCHAR | F25: 20 | I25: Y | K25: コード値：ADIPOSE/UMBILICAL/DENTAL_PULP/BONE_MARROW/PLANT/OTHER
A26: m_product | B26: 6 | C26: form | D26: 形態 | E26: VARCHAR | F26: 20 | I26: Y | K26: コード値：FROZEN/LYOPHILIZED/LIQUID
A27: m_product | B27: 7 | C27: particle_conc | D27: 粒子濃度（個/mL） | E27: NUMERIC | F27: 20,0 | K27: 仕様値。ロット実測はt_lotに保持
A28: m_product | B28: 8 | C28: volume_ml | D28: 内容量（mL） | E28: NUMERIC | F28: 8,2
A29: m_product | B29: 9 | C29: unit | D29: 販売単位 | E29: VARCHAR | F29: 10 | I29: Y | J29: 本 | K29: 本/箱/vial 等
A30: m_product | B30: 10 | C30: storage_class | D30: 保管温度区分 | E30: VARCHAR | F30: 10 | I30: Y | K30: コード値：M80/M20/COLD/RT
A31: m_product | B31: 11 | C31: shelf_life_days | D31: 有効期間（日） | E31: INTEGER | I31: Y | K31: 使用期限未記載時の自動計算用
A32: m_product | B32: 12 | C32: min_remaining_days | D32: 最低出荷残期間（日） | E32: INTEGER | I32: Y | J32: 90 | K32: 残存期間がこれ未満のロットは引当不可
A33: m_product | B33: 13 | C33: regulatory_class | D33: 規制区分 | E33: VARCHAR | F33: 20 | I33: Y | K33: コード値：COSMETIC_RAW/RESEARCH_USE/MEDICAL_USE/OTHER
A34: m_product | B34: 14 | C34: standard_cost | D34: 標準原価（円） | E34: NUMERIC | F34: 12,2
A35: m_product | B35: 15 | C35: list_price | D35: 標準売価（円） | E35: NUMERIC | F35: 12,2 | K35: 税抜
A36: m_product | B36: 16 | C36: reorder_point | D36: 発注点 | E36: INTEGER | J36: 0 | K36: 在庫下限アラート閾値
A37: m_product | B37: 17 | C37: is_active | D37: 有効フラグ | E37: BOOLEAN | I37: Y | J37: true
A38: m_product | B38: 18 | C38: created_at | D38: 作成日時 | E38: TIMESTAMPTZ | I38: Y | J38: 現在日時
A39: m_product | B39: 19 | C39: created_by | D39: 作成者 | E39: BIGINT | H39: m_user.id | I39: Y
A40: m_product | B40: 20 | C40: updated_at | D40: 更新日時 | E40: TIMESTAMPTZ | I40: Y | J40: 現在日時
...

Sheet インデックス・制約
A1: インデックス・制約定義 | E1: ← 表紙へ
A2: PK・FK制約は項目定義に従い全て作成する（FK列には別途インデックスを作成）
A3: テーブル | B3: 種別 | C3: 名前 | D3: 対象カラム | E3: 目的
A4: m_supplier | B4: UNIQUE | C4: uq_supplier_code | D4: supplier_code | E4: コード一意
A5: m_product | B5: UNIQUE | C5: uq_product_code | D5: product_code | E5: コード一意
A6: m_customer | B6: UNIQUE | C6: uq_customer_code | D6: customer_code | E6: コード一意
A7: m_customer | B7: CHECK | C7: ck_customer_medical_code | D7: customer_type, medical_inst_code | E7: BR-10：customer_type<>'MEDICAL' OR medical_inst_code IS NOT NULL
A8: m_ship_to | B8: UNIQUE(部分) | C8: uq_ship_to_default | D8: customer_id WHERE is_default | E8: 既定納品先は顧客ごとに1件
A9: m_location | B9: UNIQUE | C9: uq_location_code | D9: location_code | E9: コード一意
A10: m_location | B10: CHECK | C10: ck_location_temp | D10: temp_min, temp_max | E10: temp_min < temp_max
A11: m_sales_rule | B11: UNIQUE | C11: uq_sales_rule | D11: regulatory_class, customer_type | E11: 組合せ一意
A12: m_user | B12: UNIQUE | C12: uq_user_email | D12: email | E12: ログインID一意
A13: t_purchase_order | B13: UNIQUE | C13: uq_po_no | D13: po_no | E13: 番号一意
A14: t_purchase_order_line | B14: UNIQUE | C14: uq_po_line | D14: purchase_order_id, line_no | E14: 行番号一意
... A42: t_audit_log | B42: INDEX | C42: ix_audit_user_time | D42: user_id, occurred_at | E42: ユーザー別履歴

Sheet DDL
A1: DDL（PostgreSQL）— 項目定義・インデックス定義から自動生成 | B1: ← 表紙へ
A3: -- 生成元: docs/design/tools/spec.py（手修正しないこと）
A4: -- 作成順は外部キーの依存順
A6: -- ユーザー：システム利用者
A7: CREATE TABLE m_user (
A8: id BIGINT GENERATED ALWAYS AS IDENTITY PRIMARY KEY,
A9: email VARCHAR(254) NOT NULL,
A10: name VARCHAR(50) NOT NULL,
A11: role VARCHAR(20) NOT NULL,
A12: password_hash VARCHAR(255) NOT NULL,
A13: mfa_secret VARCHAR(255),
A14: failed_login_count INTEGER NOT NULL DEFAULT 0,
A15: is_active BOOLEAN NOT NULL DEFAULT true,
... A881: CREATE INDEX ix_audit_user_time ON t_audit_log (user_id, occurred_at);

Sheet 主要SQL
A1: 主要SQL | C1: ← 表紙へ
A3: SQL ID | B3: 用途 | C3: SQL
A4: SQL-01 | B4: ロット→出荷先顧客（前方追跡） | C4: SELECT c.customer_code, c.name AS customer_name, st.name AS ship_to_name, s.shipment_no, s.shipped_on, sl.status AS line_status, sl.quantity AS shipped_qty, COALESCE(SUM(r.quantity) FILTER (WHERE r.recall_target_id IS NULL), 0) AS returned_qty, COALESCE(SUM(r.quantity) FILTER (WHERE r.recall_target_id IS NOT NULL), 0) AS recalled_qty, CASE WHEN sl.status = 'SHIPPED' THEN sl.quantity - COALESCE(SUM(r.quantity), 0) ELSE 0 END AS net_qty FROM t_shipment_line sl JOIN t_shipment s ON s.id = sl.shipment_id JOIN m_customer c ON c.id = s.customer_id JOIN m_ship_to st ON st.id = s.ship_to_id LEFT JOIN t_return r ON r.shipment_line_id = sl.id WHERE sl.lot_id = :lot_id AND sl.status IN ('SHIPPED', 'CANCELLED') AND EXISTS (SELECT 1 FROM t_stock_movement m WHERE m.ref_type = 'shipment_line' AND m.ref_id = sl.id AND m.movement_type = 'SHIPMENT') GROUP BY c.customer_code, c.name, st.name, s.shipment_no, s.shipped_on, sl.id, sl.status, sl.quantity ORDER BY s.shipped_on, sl.id;
A5: SQL-02 | B5: 顧客→購入ロット（後方追跡） | C5: SELECT s.shipped_on, p.product_code, p.name AS product_name, l.lot_no, l.supplier_lot_no, l.expires_on, l.status AS lot_status, sl.quantity AS shipped_qty, COALESCE(SUM(r.quantity), 0) AS returned_qty, sl.quantity - COALESCE(SUM(r.quantity), 0) AS net_qty FROM t_shipment s JOIN t_shipment_line sl ON sl.shipment_id = s.id AND sl.status = 'SHIPPED' JOIN t_lot l ON l.id = sl.lot_id JOIN m_product p ON p.id = sl.product_id LEFT JOIN t_return r ON r.shipment_line_id = sl.id WHERE s.customer_id = :customer_id AND s.shipped_on BETWEEN :from AND :to GROUP BY s.shipped_on, p.product_code, p.name, l.lot_no, l.supplier_lot_no, l.expires_on, l.status, sl.id, sl.quantity ORDER BY s.shipped_on DESC;
A6: SQL-03 | B6: 回収対象抽出（P-18。再実行可・冪等） | C6: -- (1) 出荷正味数量の UPSERT。shipped_qty＝出荷数量−通常返品数量（回収品の返品は recovered_qty 側で管理するため除外） INSERT INTO t_recall_target (recall_id, customer_id, ship_to_id, lot_id, shipped_qty, recovered_qty, status, close_reason, created_by, updated_by) SELECT :recall_id, s.customer_id, s.ship_to_id, sl.lot_id, SUM(sl.quantity - COALESCE(rt.returned, 0)), 0, CASE WHEN SUM(sl.quantity - COALESCE(rt.returned, 0)) > 0 THEN 'NOT_CONTACTED' ELSE 'CLOSED' END, CASE WHEN SUM(sl.quantity - COALESCE(rt.returned, 0)) > 0 THEN NULL ELSE '自動：出荷正味0' END, :user_id, :user_id FROM t_recall_lot rl JOIN t_shipment_line sl ON sl.lot_id = rl.lot_id AND sl.status = 'SHIPPED' JOIN t_shipment s ON s.id = sl.shipment_id LEFT JOIN (SELECT shipment_line_id, SUM(quantity) AS returned FROM t_return WHERE recall_target_id IS NULL GROUP BY shipment_line_id) rt ON rt.shipment_line_id = sl.id WHERE rl.recall_id = :recall_id GROUP BY s.customer_id, s.ship_to_id, sl.lot_id ON CONFLICT (recall_id, ship_to_id, lot_id) DO UPDATE SET shipped_qty = EXCLUDED.shipped_qty, status = CASE WHEN EXCLUDED.shipped_qty = 0 AND t_recall_target.recovered_qty = 0 THEN 'CLOSED' WHEN t_recall_target.recovered_qty + t_recall_target.unrecoverable_qty >= EXCLUDED.shipped_qty THEN 'RECOVERED' ELSE t_recall_target.status END, close_reason = CASE WHEN EXCLUDED.shipped_qty = 0 AND t_recall_target.recovered_qty = 0 THEN '自動：出荷正味0' ELSE t_recall_target.close_reason END, updated_at = now(), updated_by = EXCLUDED.updated_by; -- (2) 出荷取消で SHIPPED 明細が無くなった対象を 0／CLOSED に更新 UPDATE t_recall_target t SET shipped_qty = 0, status = CASE WHEN t.recovered_qty > 0 THEN 'RECOVERED' ELSE 'CLOSED' END, close_reason = CASE WHEN t.recovered_qty > 0 THEN t.close_reason ELSE '自動：出荷取消' END, updated_at = now(), updated_by = :user_id WHERE t.recall_id = :recall_id AND t.shipped_qty <> 0 AND NOT EXISTS (SELECT 1 FROM t_shipment_line sl JOIN t_shipment s ON s.id = sl.shipment_id WHERE sl.lot_id = t.lot_id AND s.ship_to_id = t.ship_to_id AND sl.status = 'SHIPPED');
A7: SQL-04 | B7: 在庫整合性チェック：現在庫＝移動履歴合計（日次バッチ） | C7: WITH mv AS ( SELECT lot_id, location_id, SUM(quantity) AS total FROM t_stock_movement GROUP BY lot_id, location_id ) SELECT COALESCE(i.lot_id, mv.lot_id) AS lot_id, COALESCE(i.location_id, mv.location_id) AS location_id, COALESCE(i.on_hand_qty, 0) AS on_hand_qty, COALESCE(mv.total, 0) AS movement_total FROM t_inventory i FULL JOIN mv ON mv.lot_id = i.lot_id AND mv.location_id = i.location_id WHERE COALESCE(i.on_hand_qty, 0) <> COALESCE(mv.total, 0);
A8: SQL-05 | B8: 引当整合性チェック：引当済数＝ALLOCATED出荷明細合計（日次バッチ） | C8: SELECT i.lot_id, i.location_id, i.allocated_qty, COALESCE(a.qty, 0) AS allocated_lines FROM t_inventory i LEFT JOIN (SELECT lot_id, location_id, SUM(quantity) AS qty FROM t_shipment_line WHERE status = 'ALLOCATED' GROUP BY lot_id, location_id) a ON a.lot_id = i.lot_id AND a.location_id = i.location_id WHERE i.allocated_qty <> COALESCE(a.qty, 0);

Sheet コード定義
A1: コード定義 | D1: ← 表紙へ
A2: DBにはコード（英字）を格納し、画面・帳票では名称を表示する
A3: コード種別 | B3: コード | C3: 名称 | D3: 備考
A4: 由来 | B4: ADIPOSE | C4: ヒト脂肪由来幹細胞
A5: 由来 | B5: UMBILICAL | C5: ヒト臍帯由来
A6: 由来 | B6: DENTAL_PULP | C6: ヒト歯髄由来
A7: 由来 | B7: BONE_MARROW | C7: ヒト骨髄由来
A8: 由来 | B8: PLANT | C8: 植物由来
A9: 由来 | B9: OTHER | C9: その他
A10: 形態 | B10: FROZEN | C10: 凍結液
A11: 形態 | B11: LYOPHILIZED | C11: 凍結乾燥
A12: 形態 | B12: LIQUID | C12: 液体（冷蔵）
A13: ロール | B13: ADMIN | C13: 管理者
A14: ロール | B14: PURCHASE | C14: 仕入担当
A15: ロール | B15: WAREHOUSE | C15: 倉庫担当
... A18: ロール | B18: VIEWER | C18: 閲覧者
A19: 顧客区分 | B19: MEDICAL | C19: 医療機関 | D19: 医療機関コード必須
A20: 顧客区分 | B20: SALON | C20: サロン
A21: 顧客区分 | B21: DISTRIBUTOR | C21: 代理店 | D21: 代理店経由の最終販売先は代理店側の管理範囲（課題 参照）
A22: 顧客区分 | B22: RESEARCH | C22: 研究機関
A23: 顧客区分 | B23: OTHER | C23: その他
A24: 規制区分 | B24: COSMETIC_RAW | C24: 化粧品原料
A25: 規制区分 | B25: RESEARCH_USE | C25: 研究用 | D25: 研究用途以外への販売不可
A26: 規制区分 | B26: MEDICAL_USE | C26: 医療機関向け | D26: 医療機関のみ販売可
A27: 規制区分 | B27: OTHER | C27: その他
A28: 保管温度区分 | B28: M80 | C28: -80℃ | D28: 許容例：-90〜-60℃
A29: 保管温度区分 | B29: M20 | C29: -20℃ | D29: 許容例：-30〜-15℃
A30: 保管温度区分 | B30: COLD | C30: 2-8℃ | D30: 許容例：2〜8℃
A31: 保管温度区分 | B31: RT | C31: 室温 | D31: 許容例：1〜30℃
A32: ロットステータス | B32: QUARANTINE | C32: 検品待ち | D32: 引当不可
A33: ロットステータス | B33: RELEASED | C33: 合格 | D33: 引当可
A34: ロットステータス | B34: HOLD | C34: 保留 | D34: 引当不可
A35: ロットステータス | B35: REJECTED | C35: 不合格 | D35: 引当不可
A36: ロットステータス | B36: RECALLED | C36: 回収 | D36: 引当不可・出荷停止
A37: ロットステータス | B37: EXPIRED | C37: 期限切れ | D37: 引当不可
A38: ロットステータス | B38: VOID | C38: 無効 | D38: 入荷取消により無効
A39: 移動区分 | B39: RECEIPT | C39: 入荷 | D39: ＋
... A47: 移動区分 | B47: CANCEL | C47: 取消（赤伝） | D47: 元伝票の逆符号

Sheet 権限マトリクス
A1: 権限マトリクス | H1: ← 表紙へ
A2: C＝登録/更新/参照 A＝承認・判定/参照 R＝参照のみ -＝利用不可
A3: 機能ID | B3: 機能名 | C3: 管理者 ADMIN | D3: 仕入担当 PURCHASE | E3: 倉庫担当 WAREHOUSE | F3: 営業担当 SALES | G3: 品質保証 QA | H3: 閲覧者 VIEWER
A4: MST-01 | B4: 仕入先管理 | C4: C | D4: R | E4: R | F4: R | G4: R | H4: R
A5: MST-02 | B5: 商品管理 | C5: C | D5: C | E5: R | F5: R | G5: R | H5: R
A6: MST-03 | B6: 顧客管理 | C6: C | D6: R | E6: R | F6: C | G6: R | H6: R
A7: MST-04 | B7: 保管場所管理 | C7: C | D7: R | E7: C | F7: R | G7: R | H7: R
A8: MST-05 | B8: ユーザー・権限管理 | C8: C | D8: - | E8: - | F8: - | G8: - | H8: -
A9: MST-06 | B9: 販売可否ルール管理 | C9: C | D9: R | E9: R | F9: R | G9: A | H9: -
A10: PUR-01 | B10: 発注登録 | C10: C | D10: C | E10: R | F10: - | G10: R | H10: -
A11: PUR-02 | B11: 発注承認・発注書出力 | C11: A | D11: R | E11: - | F11: - | G11: R | H11: -
A12: RCV-01 | B12: 入荷登録 | C12: C | D12: R | E12: C | F12: - | G12: R | H12: R
A13: RCV-02 | B13: 受入検品 | C13: R | D13: R | E13: R | F13: - | G13: A | H13: -
A14: LOT-01 | B14: ロット一覧・詳細 | C14: R | D14: R | E14: R | F14: R | G14: R | H14: R
... A37: SYS-03 | B37: ダッシュボード | C37: R | D37: R | E37: R | F37: R | G37: R | H37: R

Sheet メッセージ一覧
A1: メッセージ一覧 | D1: ← 表紙へ
A2: {xxx} は実行時に値を埋め込む
A3: メッセージID | B3: 種別 | C3: メッセージ | D3: 発生条件
A4: MSG-E01 | B4: エラー | C4: 他のユーザーにより更新されたか、処理できない状態です。画面を再読込してください。 | D4: ステータス不一致・楽観ロック競合
A5: MSG-E05 | B5: エラー | C5: 仕入先ロット番号「{supplier_lot_no}」は既に使用期限 {expires_on} で登録されています。使用期限を確認してください。 | D5: BR-15 分納時の使用期限不一致
A6: MSG-E06 | B6: エラー | C6: 使用期限は入荷日より後の日付を入力してください。 | D6: 使用期限 <= 入荷日
A7: MSG-E07 | B7: エラー | C7: 保管場所「{location}」には入庫できません（温度区分不一致または用途不一致）。 | D7: BR-06 違反
A8: MSG-E08 | B8: エラー | C8: 合格（保留解除）にはCOA（試験成績書）の添付と受入検品の完了が必要です。未検品のロットは『検品待ち』に戻してください。 | D8: BR-08 / BR-17 違反
A9: MSG-E09 | B9: エラー | C9: 判定理由を入力してください。 | D9: 不合格・保留・保留解除で理由未入力
A10: MSG-E10 | B10: エラー | C10: 商品「{product}」（{regulatory_class}）は顧客区分「{customer_type}」に販売できません。 | D10: BR-09 違反
A11: MSG-E11 | B11: エラー | C11: 顧客または納品先が無効か、納品先が顧客に属していません。 | D11: 顧客・納品先不整合
A12: MSG-E12 | B12: エラー | C12: ロット「{lot_no}」の引当可能数（{available}）を超えています。 | D12: 在庫不足・同時更新
A13: MSG-E13 | B13: エラー | C13: ロット「{lot_no}」は現在出荷できません（{status}／残期間{days}日）。引当をやり直してください。 | D13: 出荷確定・手動引当時の再検証NG
A14: MSG-E14 | B14: エラー | C14: 返品が登録されている出荷は取消できません。 | D14: P-06 返品あり
... A37: MSG-W07 | B37: 警告 | C37: 回収対象ロットに未処分の在庫（{qty}）が残っています。 | D37: P-14

Sheet 帳票一覧
A1: 帳票一覧 | F1: ← 表紙へ
A3: 帳票ID | B3: 帳票名 | C3: 形式 | D3: 抽出条件 | E3: 主な出力項目 | F3: 関連機能ID
A4: RP-01 | B4: 発注書 | C4: PDF | D4: 発注番号 | E4: 発注番号・仕入先・商品・数量・単価・納期 | F4: PUR-02
A5: RP-02 | B5: 納品書 | C5: PDF | D5: 出荷番号 | E5: 出荷番号・顧客・納品先・商品・ロット番号・使用期限・数量・保管温度 | F5: SHP-03
A6: RP-03 | B6: 仕入実績表 | C6: 画面/CSV | D6: 期間・仕入先・商品 | E6: 入荷数量・金額、入荷取消・仕入先返品（マイナス）、純仕入 | F6: RPT-01
A7: RP-04 | B7: 販売実績表 | C7: 画面/CSV | D7: 期間・顧客・商品・営業担当 | E7: 数量・売上・原価・粗利・粗利率 | F7: RPT-02
A8: RP-05 | B8: 在庫受払表 | C8: 画面/CSV | D8: 期間・商品・ロット | E8: 期首在庫・入荷・出荷・取消・返品・仕入先返品・移動・調整・廃棄・期末在庫（移動区分別） | F8: RPT-03
A9: RP-06 | B9: トレーサビリティ台帳 | C9: PDF/CSV | D9: ロット番号 or 顧客 | E9: 入荷情報・検品結果・出荷先・出荷日・数量・返品・回収状況 | F9: RPT-04
A10: RP-07 | B10: 回収対象顧客リスト | C10: PDF/CSV | D10: 回収番号 | E10: 顧客・納品先・担当者・連絡先・ロット・出荷正味数量・連絡状況・回収数量 | F10: RCL-02
A11: RP-08 | B11: 会計連携CSV | C11: CSV | D11: 期間・種別（売上/仕入） | E11: 日付・取引先・勘定科目・金額・税区分・伝票番号 | F11: RPT-05

Sheet バッチ一覧
A1: バッチ一覧 | E1: ← 表紙へ
A3: バッチID | B3: バッチ名 | C3: 実行タイミング | D3: 処理内容 | E3: 失敗時対応
A4: B-01 | B4: 期限切れ判定 | C4: 毎日 1:00 | D4: expires_on < 当日 の RELEASED/HOLD ロットを EXPIRED に更新（履歴記録）し、P-11 で引当を解除して影響受注を通知 | E4: 管理者へメール。翌日再実行で冪等に処理
A5: B-02 | B5: アラート生成 | C5: 毎日 1:10 | D5: BR-16 の条件（期限90/30日・発注点・回収未対応7日超）でアラートを生成しメール送信 | E5: 同上
A6: B-03 | B6: 在庫・引当整合性チェック | C6: 毎日 1:30 | D6: SQL-04・SQL-05 を実行し不一致があれば管理者へ通知（自動補正はしない） | E6: 不一致内容を監査ログに記録
A7: B-04 | B7: 温度CSV取込 | C7: 毎時 0分 | D7: 所定フォルダの温度ロガーCSVを取込み P-09 を実行（測定日時が過去でも P-09 ステップ2〜4で遡及判定） | E7: 取込エラー行を管理者へ通知
A8: B-05 | B8: バックアップ確認 | C8: 毎日 6:00 | D8: 前日バックアップの成否を確認 | E8: 失敗時は管理者へ通知

Sheet 非機能要件
A1: 非機能要件 | C1: ← 表紙へ
A3: 区分 | B3: 項目 | C3: 要件
A4: 性能 | B4: 画面応答 | C4: 通常の画面表示・検索は3秒以内（データ量：想定規模の5年分）
A5: 性能 | B5: トレース検索 | C5: ロット→顧客／顧客→ロットの追跡結果を2秒以内に表示
A6: 可用性 | B6: 稼働時間 | C6: 平日 8:00〜20:00 の稼働率 99.5%以上。計画停止は事前通知
A7: データ保全 | B7: バックアップ | C7: DBは日次フルバックアップ＋PITR（7日）。バックアップは別リージョンへ保管
A8: データ保全 | B8: 保存期間 | C8: トレーサビリティ関連データ（ロット・入出荷・回収・監査ログ）は最低10年保存。法令・契約要件を確認の上確定
A9: セキュリティ | B9: 認証 | C9: パスワード12文字以上＋2要素認証。5回失敗でロック。セッション30分無操作でタイムアウト
A10: セキュリティ | B10: 認可 | C10: ロールベースアクセス制御（権限マトリクス 参照）。APIでもサーバー側で権限検証
A11: セキュリティ | B11: 通信・保存 | C11: 通信はTLS1.2以上。DB・ファイルストレージは保存時暗号化
A12: セキュリティ | B12: 個人情報 | C12: 顧客担当者の氏名・連絡先は個人情報として扱い、出力操作は監査ログに記録
A13: 監査性 | B13: 監査ログ | C13: 登録・更新・取消・ステータス変更・CSV/PDF出力・ログインを記録。ログは追記のみで改変不可
A14: 監査性 | B14: 電子記録 | C14: 確定済伝票の変更履歴（誰が・いつ・何を）を保持（ER/ES指針等の要否は課題として確認）
... A21: 拡張性 | B21: 簡易版（段階導入） | C21: 第1段階として Google スプレッドシート＋AppSheet で本設計のテーブル構造をシート化して運用し、件数・利用者増加時にWebアプリへ移行可能とする（テーブル・コード値は共通）

Sheet 課題一覧
A1: 課題一覧 | G1: ← 表紙へ
A2: 黄色セル（ステータス・回答欄）に記入してください。例：ステータス=回答済、回答=「化粧品原料のみ取扱い」
A3: No | B3: 区分 | C3: 内容 | D3: 対応方針 | E3: 期限 | F3: ステータス | G3: 回答・決定事項（記入欄）
A4: Q-01 | B4: 法規制 | C4: 取り扱うエクソソーム製品の法的区分（化粧品原料・研究用・医療用途等）と、販売可能な顧客区分の確定。再生医療等安全性確保法の改正等による規制対象化の動向確認。 | D4: 薬事専門家・行政書士へ確認し、販売可否ルール初期値を確定 | E4: 要件定義完了まで | F4: 未対応
A5: Q-02 | B5: 法規制 | C5: トレーサビリティ記録の法定保存期間の確認。 | D5: 確認結果で非機能要件『保存期間』を確定 | E5: 要件定義完了まで | F5: 未対応
A6: Q-03 | B6: 業務 | C6: 代理店経由で販売した場合、最終販売先（代理店の顧客）まで管理するか。 | D6: 代理店に販売報告をもらいCSV取込する案を検討 | E6: 基本設計完了まで | F6: 未対応
A7: Q-04 | B7: 業務 | C7: 1ロットを小分け（リパック）して販売するケースの有無。 | D7: 有りの場合は親子ロット（t_lot に parent_lot_id）を追加 | E7: 基本設計完了まで | F7: 未対応
A8: Q-05 | B8: 業務 | C8: サンプル（無償出荷）もトレース対象とするか。 | D8: 対象とする前提で、受注に『無償』区分を追加する案 | E8: 基本設計完了まで | F8: 未対応
A9: Q-06 | B9: システム | C9: 温度ロガー機器からの自動取込（API/CSV）の要否と機種。 | D9: 当面はCSV取込で対応 | E9: 詳細設計まで | F9: 未対応
A10: Q-07 | B10: システム | C10: 会計ソフト（freee/マネーフォワード/弥生 等）の機種と取込形式。 | D10: 機種確定後にRP-08の項目確定 | E10: 詳細設計まで | F10: 未対応
A11: Q-09 | B11: 業務 | C11: 与信残高の算出方法（入金情報を会計ソフトから取込むか）。 | D11: 当面は BR-11 の簡易算出。会計連携で入金データ取込を検討 | E11: 基本設計完了まで | F11: 未対応
A12: Q-10 | B12: 品質 | C12: 温度逸脱時の保留単位。現設計はロット単位（他保管場所の同ロットも停止＝安全側）。保管場所単位にするか。 | D12: QAと協議。保管場所単位にする場合は t_inventory に保留フラグを追加 | E12: 基本設計完了まで | F12: 未対応
A13: Q-08 | B13: システム | C13: 第1段階をスプレッドシート＋AppSheet で始めるか、Webアプリで始めるか。 | D13: 件数・予算・開始時期で判断 | E13: 要件定義完了まで | F13: 未対応
